Workbook

Sheet Como_usar
B1: Herramienta Demand Planner — Watt's — Grupo Lacteos Y Jugos (datos al 22-10-2026)
B3: Hojas de este libro:
B4: • Excepciones — tu tablero diario. Una fila por SKU; solo mira las que tienen alerta. Columna "Qué revisar" te dice la acción.
B5: • Stock_Seguridad — cálculo de SS, punto de reorden y techo por vida útil para cada SKU.
B6: • ABC_XYZ — segmentación de cada SKU y cómo planificarlo. Incluye calidad del forecast (WMAPE y sesgo).
B7: • Cadenas_vs_FCST — qué cadena pidió más y cuál se desvió más del forecast (S38-S41).
B8: • Parametros — celdas amarillas editables: cortes, niveles de servicio, lead time, umbrales.
B9: • Datos_Semanales — pedidos y FCST por SKU (fuente). Para actualizar: pega las semanas nuevas aquí.
B10: Convención de colores: texto azul en celda amarilla = dato que tú editas. Texto negro = fórmula. Texto verde = viene de otra hoja.
B12: 1. ¿Qué es ABC/XYZ? — Ejemplo con fórmulas (cambia los números azules y mira cómo cambia)
B13: ABC mide CUÁNTO vende el SKU (importancia). XYZ mide QUÉ TAN ESTABLE es (predictibilidad). Se cruzan en 9 segmentos.
B15: SKU ejemplo | C15: Sem 1 | D15: Sem 2 | E15: Sem 3 | F15: Sem 4 | G15: Sem 5 | H15: Sem 6 | I15: Promedio | J15: Desv. est. | K15: CV | L15: XYZ
B16: Leche entera 1L (estable) | C16: 10000 | D16: 10400 | E16: 9800 | F16: 10200 | G16: 9900 | H16: 10100 | I16: =AVERAGE(C16:H16) -> 10066.667 | J16: =STDEV(C16:H16) -> 216.02469 | K16: =J16/I16 -> 0.021459406 | L16: =IF(K16<=Parametros!$B$6,"X",IF(K16<=Parametros!$B$7,"Y","Z")) -> X
B17: Yogurt con promo (variable) | C17: 1500 | D17: 5200 | E17: 1000 | F17: 4800 | G17: 900 | H17: 3500 | I17: =AVERAGE(C17:H17) -> 2816.6667 | J17: =STDEV(C17:H17) -> 1938.4702 | K17: =J17/I17 -> 0.68821427 | L17: =IF(K17<=Parametros!$B$6,"X",IF(K17<=Parametros!$B$7,"Y","Z")) -> Y
B18: Queso especial (errático) | C18: 200 | D18: 1500 | E18: 0 | F18: 900 | G18: 50 | H18: 1800 | I18: =AVERAGE(C18:H18) -> 741.66667 | J18: =STDEV(C18:H18) -> 780.01068 | K18: =J18/I18 -> 1.0516998 | L18: =IF(K18<=Parametros!$B$6,"X",IF(K18<=Parametros!$B$7,"Y","Z")) -> Z
B20: CV (coeficiente de variación) = desviación estándar ÷ promedio. CV 0,02 = la leche vende casi igual todas las semanas → X.
B21: CV ≤ 0,5 → X (estable, se planifica con estadística). 0,5–1,0 → Y (variable, hay que entender por qué). > 1,0 → Z (errático).
B22: ABC: ordenas los SKU de mayor a menor volumen y sumas. Los que llegan al 80% del total son A; hasta el 95% son B; el resto C.
B23: Ejemplo: si un SKU es A (mucho volumen) y Z (errático) = AZ → es donde un error te cuesta más: ahí va tu tiempo.
B24: Un AX (mucho volumen, estable) casi se planifica solo: no lo toques cada semana. Un CZ (poco y errático) no merece tu tiempo: stock mínimo.
B25: Tu lista real está en la hoja ABC_XYZ; la matriz de acciones por segmento está en Parametros.
B27: 2. Stock de seguridad — Ejemplo con fórmulas
B28: El SS cubre el ERROR del forecast durante el tiempo que tardas en reponer. Por eso usa σ del error (no de la venta).
B30: FCST semanal (kg) | D30: 10000
B31: σ del error del forecast (kg/sem) | D31: 2000
B32: Lead time (semanas) | D32: 2
B33: Nivel de servicio | D33: 0.98
B34: Z (=NORMSINV(nivel)) | D34: =NORMSINV(D33) -> 2.0537489
B35: SS = Z × σ × √LT (kg) | D35: =D34*D31*SQRT(D32) -> 5808.8791
B36: Punto de reorden = SS + FCST × LT (kg) | D36: =D35+D30*D32 -> 25808.879
B37: VU del producto (días) | D37: 50
B38: Tope avance cadena más exigente | D38: 0.35
B39: Semanas vendibles = VU × tope / 7 | D39: =D37*D38/7 -> 2.5
B40: Stock máx. vendible = FCST × semanas vendibles | D40: =D30*D39 -> 25000
B41: SS final = MIN(SS, máx. vendible − FCST × LT) | D41: =MAX(0,MIN(D35,D40-D30*D32)) -> 5000
B43: Lectura: con 98% de servicio necesitas ~5.800 kg de SS. Pero si el producto dura 50 días y la cadena más exigente acepta hasta 35% de avance,
B44: solo tienes 2,5 semanas para venderlo: máx. vendible 25.000 kg − 20.000 kg que vendes durante el lead time = SS topado en 5.000 kg. Producir más = merma.
B45: Z según nivel de servicio: 90% → 1,28 · 95% → 1,64 · 98% → 2,05 · 99% → 2,33. Subir de 95% a 99% casi aumenta el SS en 42%.
B46: Dato pendiente: el lead time real por categoría (hoy se usa 1 semana por defecto). Cárgalo en Parametros y todo se recalcula.
B48: 3. Gestión por excepción — rutina sugerida
...

Sheet Parametros
A1: Parámetros — edita solo las celdas amarillas (texto azul)
A3: Parámetro | B3: Valor | C3: Nota / fuente
A4: Corte ABC: A hasta % acumulado | B4: 0.8 | C4: Pareto estándar: los SKU que suman el 80% del volumen son A.
A5: Corte ABC: B hasta % acumulado | B5: 0.95 | C5: Del 80% al 95% son B; el resto (5% del volumen) son C.
A6: Corte XYZ: X si CV ≤ | B6: 0.5 | C6: CV = desviación estándar / promedio semanal. Corte usual en demanda semanal por SKU.
A7: Corte XYZ: Y si CV ≤ | B7: 1 | C7: Sobre este valor el SKU es Z (errático).
A8: Nivel de servicio A | B8: 0.98 | C8: Supuesto inicial (benchmark internacional). Ajustar según política Watt's.
A9: Nivel de servicio B | B9: 0.95 | C9: Supuesto inicial.
A10: Nivel de servicio C | B10: 0.9 | C10: Supuesto inicial.
A11: Nivel de servicio SKU sin historial | B11: 0.95 | C11: Para SKU sin ventas en la base S36-S41.
A12: Lead time por defecto (semanas) | B12: 1 | C12: SUPUESTO: no se recibió lead time real. Reemplazar por categoría en la tabla de abajo.
A13: σ por defecto (% del FCST semanal) si no hay historial | B13: 0.3 | C13: SUPUESTO para SKU sin historial de pedidos.
A14: Umbral desviación pedido vs FCST (±) | B14: 0.2 | C14: Alerta si |Solicitado/FCST − 1| supera este valor.
A15: Volumen mínimo para alertar desviación SKU (kg, 4 sem) | B15: 2000 | C15: Evita alertas por SKU de volumen marginal.
... A18: Margen de alerta VU (puntos de avance antes del filtro) | B18: 0.06 | C18: Misma regla del dashboard: alerta si el lote está a ≤ 6 pts del tope de la cadena más exigente.
A21: Matriz ABC/XYZ — qué hacer con cada segmento
A22: Segmento | B22: Cómo planificarlo | C22: Frecuencia de revisión
A23: AX | B23: Forecast estadístico casi automático. Ajustes mínimos. SS bajo porque la demanda es estable. | C23: Mensual
A24: AY | B24: Alto volumen con variaciones: entender causas (promos, cadenas). Validar con KAM antes de ajustar. | C24: Semanal
A25: AZ | B25: FOCO MÁXIMO. Mucho volumen y errático: CPFR con cadenas, separar promociones de la base, SS alto. | C25: 2 veces por semana
A26: BX | B26: Estadístico + revisión de tendencia. | C26: Mensual
A27: BY | B27: Validar promociones y eventos con comercial. | C27: Quincenal
A28: BZ | B28: Investigar causa de la variabilidad; evaluar producir contra pedido confirmado. | C28: Semanal
A29: CX | B29: Reposición simple mín/máx. | C29: Trimestral
A30: CY | B30: Mín/máx con stock bajo; evaluar continuidad del SKU. | C30: Mensual
A31: CZ | B31: Contra pedido o stock mínimo. Candidato a racionalizar/descontinuar. | C31: Mensual
A34: Lead time de reposición por categoría (semanas) — reemplaza con el dato real
A35: Categoría | B35: Lead time (sem) | C35: Nota
A36: CREMA | B36: =Parametros!$B$12 -> 1 | C36: Usa el valor por defecto hasta que ingreses el real
A37: JUGOS Y NECTARES | B37: =Parametros!$B$12 -> 1 | C37: Usa el valor por defecto hasta que ingreses el real
A38: LECHE EVAPORADA | B38: =Parametros!$B$12 -> 1 | C38: Usa el valor por defecto hasta que ingreses el real
A39: LECHES EN POLVO | B39: =Parametros!$B$12 -> 1 | C39: Usa el valor por defecto hasta que ingreses el real
A40: LECHES LIQUIDAS | B40: =Parametros!$B$12 -> 1 | C40: Usa el valor por defecto hasta que ingreses el real
A41: MANJAR | B41: =Parametros!$B$12 -> 1 | C41: Usa el valor por defecto hasta que ingreses el real

Sheet Excepciones
A1: Tablero de excepciones — revisa solo lo que tiene alerta — Grupo Lacteos Y Jugos
A2: Ordena por Puntaje (mayor a menor) y trabaja de arriba hacia abajo. Puntaje = (Quiebre×3 + Encubierto×2 + Merma/VU×2 + Desviación×1) × peso ABC (A=3, B=2, C=1). Cada fila dice qué revisar. Datos al 22-10-2026.
A4: SKU | B4: Producto | C4: Categoría | D4: Segmento | E4: Estado stock | F4: Cobertura (sem) | G4: Stock disp (kg) | H4: SS final (kg) | I4: Punto reorden (kg) | J4: XLIB (kg) | K4: Próx. liberación | L4: Kg fuera filtro cadena exigente | M4: Kg a ≤6 pts del filtro | N4: Kg fuera de TODAS las cadenas | O4: Avance VU ponderado | P4: Tope cadena exigente | Q4: Margen (pts) | R4: Stock útil cadena exigente (kg) | S4: Solicitado 4 sem (kg) | T4: FCST 4 sem (kg) | U4: Desv. % | V4: ALERTA QUIEBRE | W4: QUIEBRE ENCUBIERTO (VU) | X4: ALERTA MERMA/VU | Y4: ALERTA DESVIACIÓN | Z4: N° alertas | AA4: Puntaje | AB4: Prioridad | AC4: Qué revisar | AE4: Resumen
A5: =Stock_Seguridad!A5 -> 30000522 | B5: =Stock_Seguridad!B5 -> LECHE BLANCA LONCO ENTERA BASE 12X1LT | C5: =Stock_Seguridad!C5 -> LECHES LIQUIDAS | D5: =Stock_Seguridad!F5 -> AX | E5: =Stock_Seguridad!X5 -> OK | F5: =Stock_Seguridad!W5 -> 1.666979 | G5: =Stock_Seguridad!T5 -> 276372 | H5: =Stock_Seguridad!R5 -> 203849.72 | I5: =Stock_Seguridad!S5 -> 530963.62 | J5: =Stock_Seguridad!U5 -> 268920 | K5: 46321 | L5: 684 | M5: 16080 | N5: 0 | O5: 0.033237672 | P5: =IF(ISNUMBER(Stock_Seguridad!N5),Stock_Seguridad!N5,"") -> 0.18848168 | Q5: =IF(AND(ISNUMBER(O5),ISNUMBER(P5)),P5-O5,"") -> 0.155244 | R5: =MAX(0,G5-N(L5)) -> 275688 | S5: =SUMIFS(Cadenas_vs_FCST!$D$17:$D$652,Cadenas_vs_FCST!$A$17:$A$652,A5) -> 1522272 | T5: =SUMIFS(Cadenas_vs_FCST!$E$17:$E$652,Cadenas_vs_FCST!$A$17:$A$652,A5) -> 1455276.1 | U5: =IF(T5>0,S5/T5-1,"") -> 0.046036548 | V5: =IF(OR(E5="BAJO SS",E5="BAJO SS (XLIB CUBRE)"),"SÍ","") | W5: =IF(AND(V5="",N(L5)>=Parametros!$B$17,G5>=H5,R5<H5),"SÍ","") | X5: =IF(OR(E5="SOBRE MAX VENDIBLE",N(N5)>=Parametros!$B$17,N(M5)>=Parametros!$B$17),"SÍ","") -> SÍ | Y5: =IF(AND(ISNUMBER(U5),MAX(S5,T5)>=Parametros!$B$15,ABS(N(U5))>Parametros!$B$14),"SÍ","") | Z5: =COUNTIF(V5:Y5,"SÍ") -> 1 | AA5: =(3*(V5="SÍ")+2*(W5="SÍ")+2*(X5="SÍ")+(Y5="SÍ"))*IF(LEFT(D5,1)="A",3,IF(OR(LEFT(D5,1)="B",D5="SIN HIST"),2,1)) -> 6 | AB5: =IF(AA5>=9,"1-ALTA",IF(AA5>=4,"2-MEDIA",IF(AA5>0,"3-BAJA",""))) -> 2-MEDIA | AC5: =IF(E5="BAJO SS","Stock + XLIB bajo el SS: riesgo real de quiebre, adelantar producción. ","")&IF(E5="BAJO SS (XLIB CUBRE)","Disponible bajo el SS; depende de liberar "&TEXT(J5,"#,##0")&" kg"&IF(ISNUMBER(K5)," el "&TEXT(K5,"dd-mm"),"")&". ","")&IF(W5="SÍ","Stock parece sano pero "&TEXT(L5,"#,##0")&" kg no pasan filtro "&Stock_Seguridad!O5&": sin ellos queda bajo el SS para esa cadena. ","")&IF(E5="SOBRE MAX VENDIBLE","Sobrestock vs vida útil: frenar producción/activar venta. ","")&IF(N(N5)>=Parametros!$B$17,TEXT(N5,"#,##0")&" kg ya no los acepta ninguna cadena: venta intermedia/liquidación. ","")&IF(N(M5)>=Parametros!$B$17,TEXT(M5,"#,##0")&" kg a punto de salir del filtro: despachar primero (FEFO). ","")&IF(Y5="SÍ","Pedidos "&IF(N(U5)>0,"sobre","bajo")&" FCST "&TEXT(ABS(N(U5)),"0%")&": revisar forecast con KAM.","") -> 16,080 kg a punto de salir del filtro: despachar primero (FEFO). | AE5: SKU con alerta de quiebre | AF5: =COUNTIF(V5:V118,"SÍ") -> 7
A6: =Stock_Seguridad!A6 -> 30000325 | B6: =Stock_Seguridad!B6 -> LECHE LONCO ENTERA S/LAC NAT 12X1LT | C6: =Stock_Seguridad!C6 -> LECHES LIQUIDAS | D6: =Stock_Seguridad!F6 -> AX | E6: =Stock_Seguridad!X6 -> OK | F6: =Stock_Seguridad!W6 -> 4.5409173 | G6: =Stock_Seguridad!T6 -> 582228 | H6: =Stock_Seguridad!R6 -> 54787.834 | I6: =Stock_Seguridad!S6 -> 236577.53 | J6: =Stock_Seguridad!U6 -> 243264 | K6: 46322 | L6: 1512 | M6: 89844 | N6: 768 | O6: 0.10510591 | P6: =IF(ISNUMBER(Stock_Seguridad!N6),Stock_Seguridad!N6,"") -> 0.25543478 | Q6: =IF(AND(ISNUMBER(O6),ISNUMBER(P6)),P6-O6,"") -> 0.15032887 | R6: =MAX(0,G6-N(L6)) -> 580716 | S6: =SUMIFS(Cadenas_vs_FCST!$D$17:$D$652,Cadenas_vs_FCST!$A$17:$A$652,A6) -> 502932 | T6: =SUMIFS(Cadenas_vs_FCST!$E$17:$E$652,Cadenas_vs_FCST!$A$17:$A$652,A6) -> 543530.18 | U6: =IF(T6>0,S6/T6-1,"") -> -0.07469351 | V6: =IF(OR(E6="BAJO SS",E6="BAJO SS (XLIB CUBRE)"),"SÍ","") | W6: =IF(AND(V6="",N(L6)>=Parametros!$B$17,G6>=H6,R6<H6),"SÍ","") | X6: =IF(OR(E6="SOBRE MAX VENDIBLE",N(N6)>=Parametros!$B$17,N(M6)>=Parametros!$B$17),"SÍ","") -> SÍ | Y6: =IF(AND(ISNUMBER(U6),MAX(S6,T6)>=Parametros!$B$15,ABS(N(U6))>Parametros!$B$14),"SÍ","") | Z6: =COUNTIF(V6:Y6,"SÍ") -> 1 | AA6: =(3*(V6="SÍ")+2*(W6="SÍ")+2*(X6="SÍ")+(Y6="SÍ"))*IF(LEFT(D6,1)="A",3,IF(OR(LEFT(D6,1)="B",D6="SIN HIST"),2,1)) -> 6 | AB6: =IF(AA6>=9,"1-ALTA",IF(AA6>=4,"2-MEDIA",IF(AA6>0,"3-BAJA",""))) -> 2-MEDIA | AC6: =IF(E6="BAJO SS","Stock + XLIB bajo el SS: riesgo real de quiebre, adelantar producción. ","")&IF(E6="BAJO SS (XLIB CUBRE)","Disponible bajo el SS; depende de liberar "&TEXT(J6,"#,##0")&" kg"&IF(ISNUMBER(K6)," el "&TEXT(K6,"dd-mm"),"")&". ","")&IF(W6="SÍ","Stock parece sano pero "&TEXT(L6,"#,##0")&" kg no pasan filtro "&Stock_Seguridad!O6&": sin ellos queda bajo el SS para esa cadena. ","")&IF(E6="SOBRE MAX VENDIBLE","Sobrestock vs vida útil: frenar producción/activar venta. ","")&IF(N(N6)>=Parametros!$B$17,TEXT(N6,"#,##0")&" kg ya no los acepta ninguna cadena: venta intermedia/liquidación. ","")&IF(N(M6)>=Parametros!$B$17,TEXT(M6,"#,##0")&" kg a punto de salir del filtro: despachar primero (FEFO). ","")&IF(Y6="SÍ","Pedidos "&IF(N(U6)>0,"sobre","bajo")&" FCST "&TEXT(ABS(N(U6)),"0%")&": revisar forecast con KAM.","") -> 768 kg ya no los acepta ninguna cadena: venta intermedia/liquidación. 89,844 kg a punto de salir del filtro: despachar primero (FEFO). | AE6: SKU con quiebre encubierto (VU) | AF6: =COUNTIF(W5:W118,"SÍ") -> 9
A7: =Stock_Seguridad!A7 -> 30000326 | B7: =Stock_Seguridad!B7 -> LECHE LONCO SEMIDESCREMADA S/LACT 12X1LT | C7: =Stock_Seguridad!C7 -> LECHES LIQUIDAS | D7: =Stock_Seguridad!F7 -> AX | E7: =Stock_Seguridad!X7 -> OK | F7: =Stock_Seguridad!W7 -> 2.2546197 | G7: =Stock_Seguridad!T7 -> 236280 | H7: =Stock_Seguridad!R7 -> 37565.447 | I7: =Stock_Seguridad!S7 -> 211357.95 | J7: =Stock_Seguridad!U7 -> 155556 | K7: 46319 | L7: 15576 | M7: 0 | N7: 4248 | O7: 0.076387075 | P7: =IF(ISNUMBER(Stock_Seguridad!N7),Stock_Seguridad!N7,"") -> 0.23913043 | Q7: =IF(AND(ISNUMBER(O7),ISNUMBER(P7)),P7-O7,"") -> 0.16274336 | R7: =MAX(0,G7-N(L7)) -> 220704 | S7: =SUMIFS(Cadenas_vs_FCST!$D$17:$D$652,Cadenas_vs_FCST!$A$17:$A$652,A7) -> 482760 | T7: =SUMIFS(Cadenas_vs_FCST!$E$17:$E$652,Cadenas_vs_FCST!$A$17:$A$652,A7) -> 521443.37 | U7: =IF(T7>0,S7/T7-1,"") -> -0.074185179 | V7: =IF(OR(E7="BAJO SS",E7="BAJO SS (XLIB CUBRE)"),"SÍ","") | W7: =IF(AND(V7="",N(L7)>=Parametros!$B$17,G7>=H7,R7<H7),"SÍ","") | X7: =IF(OR(E7="SOBRE MAX VENDIBLE",N(N7)>=Parametros!$B$17,N(M7)>=Parametros!$B$17),"SÍ","") -> SÍ | Y7: =IF(AND(ISNUMBER(U7),MAX(S7,T7)>=Parametros!$B$15,ABS(N(U7))>Parametros!$B$14),"SÍ","") | Z7: =COUNTIF(V7:Y7,"SÍ") -> 1 | AA7: =(3*(V7="SÍ")+2*(W7="SÍ")+2*(X7="SÍ")+(Y7="SÍ"))*IF(LEFT(D7,1)="A",3,IF(OR(LEFT(D7,1)="B",D7="SIN HIST"),2,1)) -> 6 | AB7: =IF(AA7>=9,"1-ALTA",IF(AA7>=4,"2-MEDIA",IF(AA7>0,"3-BAJA",""))) -> 2-MEDIA | AC7: =IF(E7="BAJO SS","Stock + XLIB bajo el SS: riesgo real de quiebre, adelantar producción. ","")&IF(E7="BAJO SS (XLIB CUBRE)","Disponible bajo el SS; depende de liberar "&TEXT(J7,"#,##0")&" kg"&IF(ISNUMBER(K7)," el "&TEXT(K7,"dd-mm"),"")&". ","")&IF(W7="SÍ","Stock parece sano pero "&TEXT(L7,"#,##0")&" kg no pasan filtro "&Stock_Seguridad!O7&": sin ellos queda bajo el SS para esa cadena. ","")&IF(E7="SOBRE MAX VENDIBLE","Sobrestock vs vida útil: frenar producción/activar venta. ","")&IF(N(N7)>=Parametros!$B$17,TEXT(N7,"#,##0")&" kg ya no los acepta ninguna cadena: venta intermedia/liquidación. ","")&IF(N(M7)>=Parametros!$B$17,TEXT(M7,"#,##0")&" kg a punto de salir del filtro: despachar primero (FEFO). ","")&IF(Y7="SÍ","Pedidos "&IF(N(U7)>0,"sobre","bajo")&" FCST "&TEXT(ABS(N(U7)),"0%")&": revisar forecast con KAM.","") -> 4,248 kg ya no los acepta ninguna cadena: venta intermedia/liquidación. | AE7: SKU con alerta merma/VU | AF7: =COUNTIF(X5:X118,"SÍ") -> 46
A8: =Stock_Seguridad!A8 -> 30000353 | B8: =Stock_Seguridad!B8 -> LECHE LONCO DESC S/LACTOSA 12X1LT | C8: =Stock_Seguridad!C8 -> LECHES LIQUIDAS | D8: =Stock_Seguridad!F8 -> AX | E8: =Stock_Seguridad!X8 -> OK | F8: =Stock_Seguridad!W8 -> 1.8538981 | G8: =Stock_Seguridad!T8 -> 218316 | H8: =Stock_Seguridad!R8 -> 51160.828 | I8: =Stock_Seguridad!S8 -> 183109.83 | J8: =Stock_Seguridad!U8 -> 26304 | K8: 46318 | L8: 2208 | M8: 252 | N8: 312 | O8: 0.071246848 | P8: =IF(ISNUMBER(Stock_Seguridad!N8),Stock_Seguridad!N8,"") -> 0.23913043 | Q8: =IF(AND(ISNUMBER(O8),ISNUMBER(P8)),P8-O8,"") -> 0.16788359 | R8: =MAX(0,G8-N(L8)) -> 216108 | S8: =SUMIFS(Cadenas_vs_FCST!$D$17:$D$652,Cadenas_vs_FCST!$A$17:$A$652,A8) -> 427464 | T8: =SUMIFS(Cadenas_vs_FCST!$E$17:$E$652,Cadenas_vs_FCST!$A$17:$A$652,A8) -> 393661.16 | U8: =IF(T8>0,S8/T8-1,"") -> 0.085867861 | V8: =IF(OR(E8="BAJO SS",E8="BAJO SS (XLIB CUBRE)"),"SÍ","") | W8: =IF(AND(V8="",N(L8)>=Parametros!$B$17,G8>=H8,R8<H8),"SÍ","") | X8: =IF(OR(E8="SOBRE MAX VENDIBLE",N(N8)>=Parametros!$B$17,N(M8)>=Parametros!$B$17),"SÍ","") | Y8: =IF(AND(ISNUMBER(U8),MAX(S8,T8)>=Parametros!$B$15,ABS(N(U8))>Parametros!$B$14),"SÍ","") | Z8: =COUNTIF(V8:Y8,"SÍ") -> 0 | AA8: =(3*(V8="SÍ")+2*(W8="SÍ")+2*(X8="SÍ")+(Y8="SÍ"))*IF(LEFT(D8,1)="A",3,IF(OR(LEFT(D8,1)="B",D8="SIN HIST"),2,1)) -> 0 | AB8: =IF(AA8>=9,"1-ALTA",IF(AA8>=4,"2-MEDIA",IF(AA8>0,"3-BAJA",""))) | AC8: =IF(E8="BAJO SS","Stock + XLIB bajo el SS: riesgo real de quiebre, adelantar producción. ","")&IF(E8="BAJO SS (XLIB CUBRE)","Disponible bajo el SS; depende de liberar "&TEXT(J8,"#,##0")&" kg"&IF(ISNUMBER(K8)," el "&TEXT(K8,"dd-mm"),"")&". ","")&IF(W8="SÍ","Stock parece sano pero "&TEXT(L8,"#,##0")&" kg no pasan filtro "&Stock_Seguridad!O8&": sin ellos queda bajo el SS para esa cadena. ","")&IF(E8="SOBRE MAX VENDIBLE","Sobrestock vs vida útil: frenar producción/activar venta. ","")&IF(N(N8)>=Parametros!$B$17,TEXT(N8,"#,##0")&" kg ya no los acepta ninguna cadena: venta intermedia/liquidación. ","")&IF(N(M8)>=Parametros!$B$17,TEXT(M8,"#,##0")&" kg a punto de salir del filtro: despachar primero (FEFO). ","")&IF(Y8="SÍ","Pedidos "&IF(N(U8)>0,"sobre","bajo")&" FCST "&TEXT(ABS(N(U8)),"0%")&": revisar forecast con KAM.","") | AE8: SKU con desviación pedido vs FCST | AF8: =COUNTIF(Y5:Y118,"SÍ") -> 42
A9: =Stock_Seguridad!A9 -> 30000523 | B9: =Stock_Seguridad!B9 -> LECHE BLANCA LONCO SEMI BASE 12X1LT | C9: =Stock_Seguridad!C9 -> LECHES LIQUIDAS | D9: =Stock_Seguridad!F9 -> AX | E9: =Stock_Seguridad!X9 -> SOBRE MAX VENDIBLE | F9: =Stock_Seguridad!W9 -> 7.3496743 | G9: =Stock_Seguridad!T9 -> 757980 | H9: =Stock_Seguridad!R9 -> 136290.41 | I9: =Stock_Seguridad!S9 -> 239421.51 | J9: =Stock_Seguridad!U9 -> 0 | L9: 318540 | M9: 102420 | N9: 768 | O9: 0.16776155 | P9: =IF(ISNUMBER(Stock_Seguridad!N9),Stock_Seguridad!N9,"") -> 0.18848168 | Q9: =IF(AND(ISNUMBER(O9),ISNUMBER(P9)),P9-O9,"") -> 0.020720129 | R9: =MAX(0,G9-N(L9)) -> 439440 | S9: =SUMIFS(Cadenas_vs_FCST!$D$17:$D$652,Cadenas_vs_FCST!$A$17:$A$652,A9) -> 273588 | T9: =SUMIFS(Cadenas_vs_FCST!$E$17:$E$652,Cadenas_vs_FCST!$A$17:$A$652,A9) -> 461942.51 | U9: =IF(T9>0,S9/T9-1,"") -> -0.40774448 | V9: =IF(OR(E9="BAJO SS",E9="BAJO SS (XLIB CUBRE)"),"SÍ","") | W9: =IF(AND(V9="",N(L9)>=Parametros!$B$17,G9>=H9,R9<H9),"SÍ","") | X9: =IF(OR(E9="SOBRE MAX VENDIBLE",N(N9)>=Parametros!$B$17,N(M9)>=Parametros!$B$17),"SÍ","") -> SÍ | Y9: =IF(AND(ISNUMBER(U9),MAX(S9,T9)>=Parametros!$B$15,ABS(N(U9))>Parametros!$B$14),"SÍ","") -> SÍ | Z9: =COUNTIF(V9:Y9,"SÍ") -> 2 | AA9: =(3*(V9="SÍ")+2*(W9="SÍ")+2*(X9="SÍ")+(Y9="SÍ"))*IF(LEFT(D9,1)="A",3,IF(OR(LEFT(D9,1)="B",D9="SIN HIST"),2,1)) -> 9 | AB9: =IF(AA9>=9,"1-ALTA",IF(AA9>=4,"2-MEDIA",IF(AA9>0,"3-BAJA",""))) -> 1-ALTA | AC9: =IF(E9="BAJO SS","Stock + XLIB bajo el SS: riesgo real de quiebre, adelantar producción. ","")&IF(E9="BAJO SS (XLIB CUBRE)","Disponible bajo el SS; depende de liberar "&TEXT(J9,"#,##0")&" kg"&IF(ISNUMBER(K9)," el "&TEXT(K9,"dd-mm"),"")&". ","")&IF(W9="SÍ","Stock parece sano pero "&TEXT(L9,"#,##0")&" kg no pasan filtro "&Stock_Seguridad!O9&": sin ellos queda bajo el SS para esa cadena. ","")&IF(E9="SOBRE MAX VENDIBLE","Sobrestock vs vida útil: frenar producción/activar venta. ","")&IF(N(N9)>=Parametros!$B$17,TEXT(N9,"#,##0")&" kg ya no los acepta ninguna cadena: venta intermedia/liquidación. ","")&IF(N(M9)>=Parametros!$B$17,TEXT(M9,"#,##0")&" kg a punto de salir del filtro: despachar primero (FEFO). ","")&IF(Y9="SÍ","Pedidos "&IF(N(U9)>0,"sobre","bajo")&" FCST "&TEXT(ABS(N(U9)),"0%")&": revisar forecast con KAM.","") -> Sobrestock vs vida útil: frenar producción/activar venta. 768 kg ya no los acepta ninguna cadena: venta intermedia/liquidación. 102,420 kg a punto de salir del filtro: despachar primero (FEFO). Pedidos bajo FCST 41%: revisar forecast con KAM. | AE9: Prioridad 1-ALTA | AF9: =COUNTIF(AB5:AB118,"1-ALTA") -> 5
A10: =Stock_Seguridad!A10 -> 30000255 | B10: =Stock_Seguridad!B10 -> NECTAR WATTS DZNO SIXPACK 30X200ML | C10: =Stock_Seguridad!C10 -> JUGOS Y NECTARES | D10: =Stock_Seguridad!F10 -> AY | E10: =Stock_Seguridad!X10 -> OK | F10: =Stock_Seguridad!W10 -> 5.2935953 | G10: =Stock_Seguridad!T10 -> 429072 | H10: =Stock_Seguridad!R10 -> 58177.81 | I10: =Stock_Seguridad!S10 -> 142305.51 | J10: =Stock_Seguridad!U10 -> 16266 | K10: 46317 | L10: 0 | M10: 0 | N10: 0 | O10: 0.052301643 | P10: =IF(ISNUMBER(Stock_Seguridad!N10),Stock_Seguridad!N10,"") -> 0.32054795 | Q10: =IF(AND(ISNUMBER(O10),ISNUMBER(P10)),P10-O10,"") -> 0.2682463 | R10: =MAX(0,G10-N(L10)) -> 429072 | S10: =SUMIFS(Cadenas_vs_FCST!$D$17:$D$652,Cadenas_vs_FCST!$A$17:$A$652,A10) -> 317406 | T10: =SUMIFS(Cadenas_vs_FCST!$E$17:$E$652,Cadenas_vs_FCST!$A$17:$A$652,A10) -> 276949.48 | U10: =IF(T10>0,S10/T10-1,"") -> 0.14607906 | V10: =IF(OR(E10="BAJO SS",E10="BAJO SS (XLIB CUBRE)"),"SÍ","") | W10: =IF(AND(V10="",N(L10)>=Parametros!$B$17,G10>=H10,R10<H10),"SÍ","") | X10: =IF(OR(E10="SOBRE MAX VENDIBLE",N(N10)>=Parametros!$B$17,N(M10)>=Parametros!$B$17),"SÍ","") | Y10: =IF(AND(ISNUMBER(U10),MAX(S10,T10)>=Parametros!$B$15,ABS(N(U10))>Parametros!$B$14),"SÍ","") | Z10: =COUNTIF(V10:Y10,"SÍ") -> 0 | AA10: =(3*(V10="SÍ")+2*(W10="SÍ")+2*(X10="SÍ")+(Y10="SÍ"))*IF(LEFT(D10,1)="A",3,IF(OR(LEFT(D10,1)="B",D10="SIN HIST"),2,1)) -> 0 | AB10: =IF(AA10>=9,"1-ALTA",IF(AA10>=4,"2-MEDIA",IF(AA10>0,"3-BAJA",""))) | AC10: =IF(E10="BAJO SS","Stock + XLIB bajo el SS: riesgo real de quiebre, adelantar producción. ","")&IF(E10="BAJO SS (XLIB CUBRE)","Disponible bajo el SS; depende de liberar "&TEXT(J10,"#,##0")&" kg"&IF(ISNUMBER(K10)," el "&TEXT(K10,"dd-mm"),"")&". ","")&IF(W10="SÍ","Stock parece sano pero "&TEXT(L10,"#,##0")&" kg no pasan filtro "&Stock_Seguridad!O10&": sin ellos queda bajo el SS para esa cadena. ","")&IF(E10="SOBRE MAX VENDIBLE","Sobrestock vs vida útil: frenar producción/activar venta. ","")&IF(N(N10)>=Parametros!$B$17,TEXT(N10,"#,##0")&" kg ya no los acepta ninguna cadena: venta intermedia/liquidación. ","")&IF(N(M10)>=Parametros!$B$17,TEXT(M10,"#,##0")&" kg a punto de salir del filtro: despachar primero (FEFO). ","")&IF(Y10="SÍ","Pedidos "&IF(N(U10)>0,"sobre","bajo")&" FCST "&TEXT(ABS(N(U10)),"0%")&": revisar forecast con KAM.","") | AE10: Prioridad 2-MEDIA | AF10: =COUNTIF(AB5:AB118,"2-MEDIA") -> 34
A11: =Stock_Seguridad!A11 -> 30000524 | B11: =Stock_Seguridad!B11 -> LECHE BLANCA LONCO DESC BASE 12X1LT | C11: =Stock_Seguridad!C11 -> LECHES LIQUIDAS | D11: =Stock_Seguridad!F11 -> AZ | E11: =Stock_Seguridad!X11 -> BAJO P.REORDEN | F11: =Stock_Seguridad!W11 -> 2.9294902 | G11: =Stock_Seguridad!T11 -> 208800 | H11: =Stock_Seguridad!R11 -> 205028.97 | I11: =Stock_Seguridad!S11 -> 276304.17 | J11: =Stock_Seguridad!U11 -> 0 | L11: 4020 | M11: 8232 | N11: 4020 | O11: 0.09304873 | P11: =IF(ISNUMBER(Stock_Seguridad!N11),Stock_Seguridad!N11,"") -> 0.18848168 | Q11: =IF(AND(ISNUMBER(O11),ISNUMBER(P11)),P11-O11,"") -> 0.095432945 | R11: =MAX(0,G11-N(L11)) -> 204780 | S11: =SUMIFS(Cadenas_vs_FCST!$D$17:$D$652,Cadenas_vs_FCST!$A$17:$A$652,A11) -> 426432 | T11: =SUMIFS(Cadenas_vs_FCST!$E$17:$E$652,Cadenas_vs_FCST!$A$17:$A$652,A11) -> 225993.6 | U11: =IF(T11>0,S11/T11-1,"") -> 0.88692067 | V11: =IF(OR(E11="BAJO SS",E11="BAJO SS (XLIB CUBRE)"),"SÍ","") | W11: =IF(AND(V11="",N(L11)>=Parametros!$B$17,G11>=H11,R11<H11),"SÍ","") -> SÍ | X11: =IF(OR(E11="SOBRE MAX VENDIBLE",N(N11)>=Parametros!$B$17,N(M11)>=Parametros!$B$17),"SÍ","") -> SÍ | Y11: =IF(AND(ISNUMBER(U11),MAX(S11,T11)>=Parametros!$B$15,ABS(N(U11))>Parametros!$B$14),"SÍ","") -> SÍ | Z11: =COUNTIF(V11:Y11,"SÍ") -> 3 | AA11: =(3*(V11="SÍ")+2*(W11="SÍ")+2*(X11="SÍ")+(Y11="SÍ"))*IF(LEFT(D11,1)="A",3,IF(OR(LEFT(D11,1)="B",D11="SIN HIST"),2,1)) -> 15 | AB11: =IF(AA11>=9,"1-ALTA",IF(AA11>=4,"2-MEDIA",IF(AA11>0,"3-BAJA",""))) -> 1-ALTA | AC11: =IF(E11="BAJO SS","Stock + XLIB bajo el SS: riesgo real de quiebre, adelantar producción. ","")&IF(E11="BAJO SS (XLIB CUBRE)","Disponible bajo el SS; depende de liberar "&TEXT(J11,"#,##0")&" kg"&IF(ISNUMBER(K11)," el "&TEXT(K11,"dd-mm"),"")&". ","")&IF(W11="SÍ","Stock parece sano pero "&TEXT(L11,"#,##0")&" kg no pasan filtro "&Stock_Seguridad!O11&": sin ellos queda bajo el SS para esa cadena. ","")&IF(E11="SOBRE MAX VENDIBLE","Sobrestock vs vida útil: frenar producción/activar venta. ","")&IF(N(N11)>=Parametros!$B$17,TEXT(N11,"#,##0")&" kg ya no los acepta ninguna cadena: venta intermedia/liquidación. ","")&IF(N(M11)>=Parametros!$B$17,TEXT(M11,"#,##0")&" kg a punto de salir del filtro: despachar primero (FEFO). ","")&IF(Y11="SÍ","Pedidos "&IF(N(U11)>0,"sobre","bajo")&" FCST "&TEXT(ABS(N(U11)),"0%")&": revisar forecast con KAM.","") -> Stock parece sano pero 4,020 kg no pasan filtro CENCOSUD CENTRAL: sin ellos queda bajo el SS para esa cadena. 4,020 kg ya no los acepta ninguna cadena: venta intermedia/liquidación. 8,232 kg a punto de salir del filtro: despachar primero (FEFO). Pedidos sobre FCST 89%: revisar forecast con KAM. | AE11: Kg fuera de filtro cadena exigente | AF11: =SUM(L5:L118) -> 444051.37
A12: =Stock_Seguridad!A12 -> 30000256 | B12: =Stock_Seguridad!B12 -> NECTAR WATTS PIÑA SIXPACK 30X200ML | C12: =Stock_Seguridad!C12 -> JUGOS Y NECTARES | D12: =Stock_Seguridad!F12 -> AY | E12: =Stock_Seguridad!X12 -> OK | F12: =Stock_Seguridad!W12 -> 3.7490697 | G12: =Stock_Seguridad!T12 -> 222156 | H12: =Stock_Seguridad!R12 -> 54208.244 | I12: =Stock_Seguridad!S12 -> 113464.54 | J12: =Stock_Seguridad!U12 -> 0 | L12: 306 | M12: 2436 | N12: 0 | O12: 0.10928945 | P12: =IF(ISNUMBER(Stock_Seguridad!N12),Stock_Seguridad!N12,"") -> 0.32054795 | Q12: =IF(AND(ISNUMBER(O12),ISNUMBER(P12)),P12-O12,"") -> 0.2112585 | R12: =MAX(0,G12-N(L12)) -> 221850 | S12: =SUMIFS(Cadenas_vs_FCST!$D$17:$D$652,Cadenas_vs_FCST!$A$17:$A$652,A12) -> 223524 | T12: =SUMIFS(Cadenas_vs_FCST!$E$17:$E$652,Cadenas_vs_FCST!$A$17:$A$652,A12) -> 203815.38 | U12: =IF(T12>0,S12/T12-1,"") -> 0.096698413 | V12: =IF(OR(E12="BAJO SS",E12="BAJO SS (XLIB CUBRE)"),"SÍ","") | W12: =IF(AND(V12="",N(L12)>=Parametros!$B$17,G12>=H12,R12<H12),"SÍ","") | X12: =IF(OR(E12="SOBRE MAX VENDIBLE",N(N12)>=Parametros!$B$17,N(M12)>=Parametros!$B$17),"SÍ","") -> SÍ | Y12: =IF(AND(ISNUMBER(U12),MAX(S12,T12)>=Parametros!$B$15,ABS(N(U12))>Parametros!$B$14),"SÍ","") | Z12: =COUNTIF(V12:Y12,"SÍ") -> 1 | AA12: =(3*(V12="SÍ")+2*(W12="SÍ")+2*(X12="SÍ")+(Y12="SÍ"))*IF(LEFT(D12,1)="A",3,IF(OR(LEFT(D12,1)="B",D12="SIN HIST"),2,1)) -> 6 | AB12: =IF(AA12>=9,"1-ALTA",IF(AA12>=4,"2-MEDIA",IF(AA12>0,"3-BAJA",""))) -> 2-MEDIA | AC12: =IF(E12="BAJO SS","Stock + XLIB bajo el SS: riesgo real de quiebre, adelantar producción. ","")&IF(E12="BAJO SS (XLIB CUBRE)","Disponible bajo el SS; depende de liberar "&TEXT(J12,"#,##0")&" kg"&IF(ISNUMBER(K12)," el "&TEXT(K12,"dd-mm"),"")&". ","")&IF(W12="SÍ","Stock parece sano pero "&TEXT(L12,"#,##0")&" kg no pasan filtro "&Stock_Seguridad!O12&": sin ellos queda bajo el SS para esa cadena. ","")&IF(E12="SOBRE MAX VENDIBLE","Sobrestock vs vida útil: frenar producción/activar venta. ","")&IF(N(N12)>=Parametros!$B$17,TEXT(N12,"#,##0")&" kg ya no los acepta ninguna cadena: venta intermedia/liquidación. ","")&IF(N(M12)>=Parametros!$B$17,TEXT(M12,"#,##0")&" kg a punto de salir del filtro: despachar primero (FEFO). ","")&IF(Y12="SÍ","Pedidos "&IF(N(U12)>0,"sobre","bajo")&" FCST "&TEXT(ABS(N(U12)),"0%")&": revisar forecast con KAM.","") -> 2,436 kg a punto de salir del filtro: despachar primero (FEFO). | AE12: Kg fuera de TODAS las cadenas | AF12: =SUM(N5:N118) -> 18608.7
A13: =Stock_Seguridad!A13 -> 30000257 | B13: =Stock_Seguridad!B13 -> NECTAR WATTS MZNA SIXPACK 30X200ML | C13: =Stock_Seguridad!C13 -> JUGOS Y NECTARES | D13: =Stock_Seguridad!F13 -> AX | E13: =Stock_Seguridad!X13 -> OK | F13: =Stock_Seguridad!W13 -> 5.8345525 | G13: =Stock_Seguridad!T13 -> 325398 | H13: =Stock_Seguridad!R13 -> 39827.553 | I13: =Stock_Seguridad!S13 -> 95741.353 | J13: =Stock_Seguridad!U13 -> 834 | K13: 46263 | L13: 0 | M13: 3690 | N13: 0 | O13: 0.079453459 | P13: =IF(ISNUMBER(Stock_Seguridad!N13),Stock_Seguridad!N13,"") -> 0.32054795 | Q13: =IF(AND(ISNUMBER(O13),ISNUMBER(P13)),P13-O13,"") -> 0.24109449 | R13: =MAX(0,G13-N(L13)) -> 325398 | S13: =SUMIFS(Cadenas_vs_FCST!$D$17:$D$652,Cadenas_vs_FCST!$A$17:$A$652,A13) -> 209526 | T13: =SUMIFS(Cadenas_vs_FCST!$E$17:$E$652,Cadenas_vs_FCST!$A$17:$A$652,A13) -> 224854.5 | U13: =IF(T13>0,S13/T13-1,"") -> -0.068170753 | V13: =IF(OR(E13="BAJO SS",E13="BAJO SS (XLIB CUBRE)"),"SÍ","") | W13: =IF(AND(V13="",N(L13)>=Parametros!$B$17,G13>=H13,R13<H13),"SÍ","") | X13: =IF(OR(E13="SOBRE MAX VENDIBLE",N(N13)>=Parametros!$B$17,N(M13)>=Parametros!$B$17),"SÍ","") -> SÍ | Y13: =IF(AND(ISNUMBER(U13),MAX(S13,T13)>=Parametros!$B$15,ABS(N(U13))>Parametros!$B$14),"SÍ","") | Z13: =COUNTIF(V13:Y13,"SÍ") -> 1 | AA13: =(3*(V13="SÍ")+2*(W13="SÍ")+2*(X13="SÍ")+(Y13="SÍ"))*IF(LEFT(D13,1)="A",3,IF(OR(LEFT(D13,1)="B",D13="SIN HIST"),2,1)) -> 6 | AB13: =IF(AA13>=9,"1-ALTA",IF(AA13>=4,"2-MEDIA",IF(AA13>0,"3-BAJA",""))) -> 2-MEDIA | AC13: =IF(E13="BAJO SS","Stock + XLIB bajo el SS: riesgo real de quiebre, adelantar producción. ","")&IF(E13="BAJO SS (XLIB CUBRE)","Disponible bajo el SS; depende de liberar "&TEXT(J13,"#,##0")&" kg"&IF(ISNUMBER(K13)," el "&TEXT(K13,"dd-mm"),"")&". ","")&IF(W13="SÍ","Stock parece sano pero "&TEXT(L13,"#,##0")&" kg no pasan filtro "&Stock_Seguridad!O13&": sin ellos queda bajo el SS para esa cadena. ","")&IF(E13="SOBRE MAX VENDIBLE","Sobrestock vs vida útil: frenar producción/activar venta. ","")&IF(N(N13)>=Parametros!$B$17,TEXT(N13,"#,##0")&" kg ya no los acepta ninguna cadena: venta intermedia/liquidación. ","")&IF(N(M13)>=Parametros!$B$17,TEXT(M13,"#,##0")&" kg a punto de salir del filtro: despachar primero (FEFO). ","")&IF(Y13="SÍ","Pedidos "&IF(N(U13)>0,"sobre","bajo")&" FCST "&TEXT(ABS(N(U13)),"0%")&": revisar forecast con KAM.","") -> 3,690 kg a punto de salir del filtro: despachar primero (FEFO).
A14: =Stock_Seguridad!A14 -> 30000258 | B14: =Stock_Seguridad!B14 -> NECTAR WATTS NJA SIXPACK 30X200ML | C14: =Stock_Seguridad!C14 -> JUGOS Y NECTARES | D14: =Stock_Seguridad!F14 -> AY | E14: =Stock_Seguridad!X14 -> OK | F14: =Stock_Seguridad!W14 -> 3.326752 | G14: =Stock_Seguridad!T14 -> 165294 | H14: =Stock_Seguridad!R14 -> 50190.009 | I14: =Stock_Seguridad!S14 -> 99876.309 | J14: =Stock_Seguridad!U14 -> 0 | L14: 0 | M14: 0 | N14: 0 | O14: 0.18631696 | P14: =IF(ISNUMBER(Stock_Seguridad!N14),Stock_Seguridad!N14,"") -> 0.32054795 | Q14: =IF(AND(ISNUMBER(O14),ISNUMBER(P14)),P14-O14,"") -> 0.13423099 | R14: =MAX(0,G14-N(L14)) -> 165294 | S14: =SUMIFS(Cadenas_vs_FCST!$D$17:$D$652,Cadenas_vs_FCST!$A$17:$A$652,A14) -> 150780 | T14: =SUMIFS(Cadenas_vs_FCST!$E$17:$E$652,Cadenas_vs_FCST!$A$17:$A$652,A14) -> 241835.55 | U14: =IF(T14>0,S14/T14-1,"") -> -0.37651846 | V14: =IF(OR(E14="BAJO SS",E14="BAJO SS (XLIB CUBRE)"),"SÍ","") | W14: =IF(AND(V14="",N(L14)>=Parametros!$B$17,G14>=H14,R14<H14),"SÍ","") | X14: =IF(OR(E14="SOBRE MAX VENDIBLE",N(N14)>=Parametros!$B$17,N(M14)>=Parametros!$B$17),"SÍ","") | Y14: =IF(AND(ISNUMBER(U14),MAX(S14,T14)>=Parametros!$B$15,ABS(N(U14))>Parametros!$B$14),"SÍ","") -> SÍ | Z14: =COUNTIF(V14:Y14,"SÍ") -> 1 | AA14: =(3*(V14="SÍ")+2*(W14="SÍ")+2*(X14="SÍ")+(Y14="SÍ"))*IF(LEFT(D14,1)="A",3,IF(OR(LEFT(D14,1)="B",D14="SIN HIST"),2,1)) -> 3 | AB14: =IF(AA14>=9,"1-ALTA",IF(AA14>=4,"2-MEDIA",IF(AA14>0,"3-BAJA",""))) -> 3-BAJA | AC14: =IF(E14="BAJO SS","Stock + XLIB bajo el SS: riesgo real de quiebre, adelantar producción. ","")&IF(E14="BAJO SS (XLIB CUBRE)","Disponible bajo el SS; depende de liberar "&TEXT(J14,"#,##0")&" kg"&IF(ISNUMBER(K14)," el "&TEXT(K14,"dd-mm"),"")&". ","")&IF(W14="SÍ","Stock parece sano pero "&TEXT(L14,"#,##0")&" kg no pasan filtro "&Stock_Seguridad!O14&": sin ellos queda bajo el SS para esa cadena. ","")&IF(E14="SOBRE MAX VENDIBLE","Sobrestock vs vida útil: frenar producción/activar venta. ","")&IF(N(N14)>=Parametros!$B$17,TEXT(N14,"#,##0")&" kg ya no los acepta ninguna cadena: venta intermedia/liquidación. ","")&IF(N(M14)>=Parametros!$B$17,TEXT(M14,"#,##0")&" kg a punto de salir del filtro: despachar primero (FEFO). ","")&IF(Y14="SÍ","Pedidos "&IF(N(U14)>0,"sobre","bajo")&" FCST "&TEXT(ABS(N(U14)),"0%")&": revisar forecast con KAM.","") -> Pedidos bajo FCST 38%: revisar forecast con KAM.
A15: =Stock_Seguridad!A15 -> 30000481 | B15: =Stock_Seguridad!B15 -> LECHE LONCO EXTRA PROTEINA 12X1LT | C15: =Stock_Seguridad!C15 -> LECHES LIQUIDAS | D15: =Stock_Seguridad!F15 -> AX | E15: =Stock_Seguridad!X15 -> OK | F15: =Stock_Seguridad!W15 -> 3.9810244 | G15: =Stock_Seguridad!T15 -> 114012 | H15: =Stock_Seguridad!R15 -> 29103.242 | I15: =Stock_Seguridad!S15 -> 69618.442 | J15: =Stock_Seguridad!U15 -> 47280 | K15: 46318 | L15: 972 | M15: 112992 | N15: 144 | O15: 0.16948128 | P15: =IF(ISNUMBER(Stock_Seguridad!N15),Stock_Seguridad!N15,"") -> 0.25925926 | Q15: =IF(AND(ISNUMBER(O15),ISNUMBER(P15)),P15-O15,"") -> 0.089777976 | R15: =MAX(0,G15-N(L15)) -> 113040 | S15: =SUMIFS(Cadenas_vs_FCST!$D$17:$D$652,Cadenas_vs_FCST!$A$17:$A$652,A15) -> 134016 | T15: =SUMIFS(Cadenas_vs_FCST!$E$17:$E$652,Cadenas_vs_FCST!$A$17:$A$652,A15) -> 139268.35 | U15: =IF(T15>0,S15/T15-1,"") -> -0.037713907 | V15: =IF(OR(E15="BAJO SS",E15="BAJO SS (XLIB CUBRE)"),"SÍ","") | W15: =IF(AND(V15="",N(L15)>=Parametros!$B$17,G15>=H15,R15<H15),"SÍ","") | X15: =IF(OR(E15="SOBRE MAX VENDIBLE",N(N15)>=Parametros!$B$17,N(M15)>=Parametros!$B$17),"SÍ","") -> SÍ | Y15: =IF(AND(ISNUMBER(U15),MAX(S15,T15)>=Parametros!$B$15,ABS(N(U15))>Parametros!$B$14),"SÍ","") | Z15: =COUNTIF(V15:Y15,"SÍ") -> 1 | AA15: =(3*(V15="SÍ")+2*(W15="SÍ")+2*(X15="SÍ")+(Y15="SÍ"))*IF(LEFT(D15,1)="A",3,IF(OR(LEFT(D15,1)="B",D15="SIN HIST"),2,1)) -> 6 | AB15: =IF(AA15>=9,"1-ALTA",IF(AA15>=4,"2-MEDIA",IF(AA15>0,"3-BAJA",""))) -> 2-MEDIA | AC15: =IF(E15="BAJO SS","Stock + XLIB bajo el SS: riesgo real de quiebre, adelantar producción. ","")&IF(E15="BAJO SS (XLIB CUBRE)","Disponible bajo el SS; depende de liberar "&TEXT(J15,"#,##0")&" kg"&IF(ISNUMBER(K15)," el "&TEXT(K15,"dd-mm"),"")&". ","")&IF(W15="SÍ","Stock parece sano pero "&TEXT(L15,"#,##0")&" kg no pasan filtro "&Stock_Seguridad!O15&": sin ellos queda bajo el SS para esa cadena. ","")&IF(E15="SOBRE MAX VENDIBLE","Sobrestock vs vida útil: frenar producción/activar venta. ","")&IF(N(N15)>=Parametros!$B$17,TEXT(N15,"#,##0")&" kg ya no los acepta ninguna cadena: venta intermedia/liquidación. ","")&IF(N(M15)>=Parametros!$B$17,TEXT(M15,"#,##0")&" kg a punto de salir del filtro: despachar primero (FEFO). ","")&IF(Y15="SÍ","Pedidos "&IF(N(U15)>0,"sobre","bajo")&" FCST "&TEXT(ABS(N(U15)),"0%")&": revisar forecast con KAM.","") -> 112,992 kg a punto de salir del filtro: despachar primero (FEFO).
A16: =Stock_Seguridad!A16 -> 30000309 | B16: =Stock_Seguridad!B16 -> YOGU YOGU MORA 30X200GR | C16: =Stock_Seguridad!C16 -> LECHES LIQUIDAS | D16: =Stock_Seguridad!F16 -> AX | E16: =Stock_Seguridad!X16 -> OK | F16: =Stock_Seguridad!W16 -> 3.3867875 | G16: =Stock_Seguridad!T16 -> 136686 | H16: =Stock_Seguridad!R16 -> 5302.3633 | I16: =Stock_Seguridad!S16 -> 45660.963 | J16: =Stock_Seguridad!U16 -> 0 | L16: 1188 | M16: 32928 | N16: 0 | O16: 0.105551 | P16: =IF(ISNUMBER(Stock_Seguridad!N16),Stock_Seguridad!N16,"") -> 0.24081633 | Q16: =IF(AND(ISNUMBER(O16),ISNUMBER(P16)),P16-O16,"") -> 0.13526533 | R16: =MAX(0,G16-N(L16)) -> 135498 | S16: =SUMIFS(Cadenas_vs_FCST!$D$17:$D$652,Cadenas_vs_FCST!$A$17:$A$652,A16) -> 151452 | T16: =SUMIFS(Cadenas_vs_FCST!$E$17:$E$652,Cadenas_vs_FCST!$A$17:$A$652,A16) -> 156937.08 | U16: =IF(T16>0,S16/T16-1,"") -> -0.034950824 | V16: =IF(OR(E16="BAJO SS",E16="BAJO SS (XLIB CUBRE)"),"SÍ","") | W16: =IF(AND(V16="",N(L16)>=Parametros!$B$17,G16>=H16,R16<H16),"SÍ","") | X16: =IF(OR(E16="SOBRE MAX VENDIBLE",N(N16)>=Parametros!$B$17,N(M16)>=Parametros!$B$17),"SÍ","") -> SÍ | Y16: =IF(AND(ISNUMBER(U16),MAX(S16,T16)>=Parametros!$B$15,ABS(N(U16))>Parametros!$B$14),"SÍ","") | Z16: =COUNTIF(V16:Y16,"SÍ") -> 1 | AA16: =(3*(V16="SÍ")+2*(W16="SÍ")+2*(X16="SÍ")+(Y16="SÍ"))*IF(LEFT(D16,1)="A",3,IF(OR(LEFT(D16,1)="B",D16="SIN HIST"),2,1)) -> 6 | AB16: =IF(AA16>=9,"1-ALTA",IF(AA16>=4,"2-MEDIA",IF(AA16>0,"3-BAJA",""))) -> 2-MEDIA | AC16: =IF(E16="BAJO SS","Stock + XLIB bajo el SS: riesgo real de quiebre, adelantar producción. ","")&IF(E16="BAJO SS (XLIB CUBRE)","Disponible bajo el SS; depende de liberar "&TEXT(J16,"#,##0")&" kg"&IF(ISNUMBER(K16)," el "&TEXT(K16,"dd-mm"),"")&". ","")&IF(W16="SÍ","Stock parece sano pero "&TEXT(L16,"#,##0")&" kg no pasan filtro "&Stock_Seguridad!O16&": sin ellos queda bajo el SS para esa cadena. ","")&IF(E16="SOBRE MAX VENDIBLE","Sobrestock vs vida útil: frenar producción/activar venta. ","")&IF(N(N16)>=Parametros!$B$17,TEXT(N16,"#,##0")&" kg ya no los acepta ninguna cadena: venta intermedia/liquidación. ","")&IF(N(M16)>=Parametros!$B$17,TEXT(M16,"#,##0")&" kg a punto de salir del filtro: despachar primero (FEFO). ","")&IF(Y16="SÍ","Pedidos "&IF(N(U16)>0,"sobre","bajo")&" FCST "&TEXT(ABS(N(U16)),"0%")&": revisar forecast con KAM.","") -> 32,928 kg a punto de salir del filtro: despachar primero (FEFO).
A17: =Stock_Seguridad!A17 -> 30000400 | B17: =Stock_Seguridad!B17 -> LECHE CHOC LONCO 30X200ML | C17: =Stock_Seguridad!C17 -> LECHES LIQUIDAS | D17: =Stock_Seguridad!F17 -> AX | E17: =Stock_Seguridad!X17 -> OK | F17: =Stock_Seguridad!W17 -> 4.2464086 | G17: =Stock_Seguridad!T17 -> 57756 | H17: =Stock_Seguridad!R17 -> 14461.343 | I17: =Stock_Seguridad!S17 -> 46495.943 | J17: =Stock_Seguridad!U17 -> 78276 | K17: 46320 | L17: 0 | M17: 72 | N17: 0 | O17: 0.047700314 | P17: =IF(ISNUMBER(Stock_Seguridad!N17),Stock_Seguridad!N17,"") -> 0.23831776 | Q17: =IF(AND(ISNUMBER(O17),ISNUMBER(P17)),P17-O17,"") -> 0.19061744 | R17: =MAX(0,G17-N(L17)) -> 57756 | S17: =SUMIFS(Cadenas_vs_FCST!$D$17:$D$652,Cadenas_vs_FCST!$A$17:$A$652,A17) -> 174120 | T17: =SUMIFS(Cadenas_vs_FCST!$E$17:$E$652,Cadenas_vs_FCST!$A$17:$A$652,A17) -> 145442.72 | U17: =IF(T17>0,S17/T17-1,"") -> 0.19717232 | V17: =IF(OR(E17="BAJO SS",E17="BAJO SS (XLIB CUBRE)"),"SÍ","") | W17: =IF(AND(V17="",N(L17)>=Parametros!$B$17,G17>=H17,R17<H17),"SÍ","") | X17: =IF(OR(E17="SOBRE MAX VENDIBLE",N(N17)>=Parametros!$B$17,N(M17)>=Parametros!$B$17),"SÍ","") | Y17: =IF(AND(ISNUMBER(U17),MAX(S17,T17)>=Parametros!$B$15,ABS(N(U17))>Parametros!$B$14),"SÍ","") | Z17: =COUNTIF(V17:Y17,"SÍ") -> 0 | AA17: =(3*(V17="SÍ")+2*(W17="SÍ")+2*(X17="SÍ")+(Y17="SÍ"))*IF(LEFT(D17,1)="A",3,IF(OR(LEFT(D17,1)="B",D17="SIN HIST"),2,1)) -> 0 | AB17: =IF(AA17>=9,"1-ALTA",IF(AA17>=4,"2-MEDIA",IF(AA17>0,"3-BAJA",""))) | AC17: =IF(E17="BAJO SS","Stock + XLIB bajo el SS: riesgo real de quiebre, adelantar producción. ","")&IF(E17="BAJO SS (XLIB CUBRE)","Disponible bajo el SS; depende de liberar "&TEXT(J17,"#,##0")&" kg"&IF(ISNUMBER(K17)," el "&TEXT(K17,"dd-mm"),"")&". ","")&IF(W17="SÍ","Stock parece sano pero "&TEXT(L17,"#,##0")&" kg no pasan filtro "&Stock_Seguridad!O17&": sin ellos queda bajo el SS para esa cadena. ","")&IF(E17="SOBRE MAX VENDIBLE","Sobrestock vs vida útil: frenar producción/activar venta. ","")&IF(N(N17)>=Parametros!$B$17,TEXT(N17,"#,##0")&" kg ya no los acepta ninguna cadena: venta intermedia/liquidación. ","")&IF(N(M17)>=Parametros!$B$17,TEXT(M17,"#,##0")&" kg a punto de salir del filtro: despachar primero (FEFO). ","")&IF(Y17="SÍ","Pedidos "&IF(N(U17)>0,"sobre","bajo")&" FCST "&TEXT(ABS(N(U17)),"0%")&": revisar forecast con KAM.","")
A18: =Stock_Seguridad!A18 -> 30000514 | B18: =Stock_Seguridad!B18 -> LECHE LONCO PROTEIN MILK CAPP 12X1LT | C18: =Stock_Seguridad!C18 -> LECHES LIQUIDAS | D18: =Stock_Seguridad!F18 -> AX | E18: =Stock_Seguridad!X18 -> BAJO P.REORDEN | F18: =Stock_Seguridad!W18 -> 1.1256679 | G18: =Stock_Seguridad!T18 -> 31284 | H18: =Stock_Seguridad!R18 -> 14942.281 | I18: =Stock_Seguridad!S18 -> 42733.781 | J18: =Stock_Seguridad!U18 -> 0 | L18: 2976 | M18: 3672 | N18: 0 | O18: 0.088589547 | P18: =IF(ISNUMBER(Stock_Seguridad!N18),Stock_Seguridad!N18,"") -> 0.21875 | Q18: =IF(AND(ISNUMBER(O18),ISNUMBER(P18)),P18-O18,"") -> 0.13016045 | R18: =MAX(0,G18-N(L18)) -> 28308 | S18: =SUMIFS(Cadenas_vs_FCST!$D$17:$D$652,Cadenas_vs_FCST!$A$17:$A$652,A18) -> 93684 | T18: =SUMIFS(Cadenas_vs_FCST!$E$17:$E$652,Cadenas_vs_FCST!$A$17:$A$652,A18) -> 78905.377 | U18: =IF(T18>0,S18/T18-1,"") -> 0.18729551 | V18: =IF(OR(E18="BAJO SS",E18="BAJO SS (XLIB CUBRE)"),"SÍ","") | W18: =IF(AND(V18="",N(L18)>=Parametros!$B$17,G18>=H18,R18<H18),"SÍ","") | X18: =IF(OR(E18="SOBRE MAX VENDIBLE",N(N18)>=Parametros!$B$17,N(M18)>=Parametros!$B$17),"SÍ","") -> SÍ | Y18: =IF(AND(ISNUMBER(U18),MAX(S18,T18)>=Parametros!$B$15,ABS(N(U18))>Parametros!$B$14),"SÍ","") | Z18: =COUNTIF(V18:Y18,"SÍ") -> 1 | AA18: =(3*(V18="SÍ")+2*(W18="SÍ")+2*(X18="SÍ")+(Y18="SÍ"))*IF(LEFT(D18,1)="A",3,IF(OR(LEFT(D18,1)="B",D18="SIN HIST"),2,1)) -> 6 | AB18: =IF(AA18>=9,"1-ALTA",IF(AA18>=4,"2-MEDIA",IF(AA18>0,"3-BAJA",""))) -> 2-MEDIA | AC18: =IF(E18="BAJO SS","Stock + XLIB bajo el SS: riesgo real de quiebre, adelantar producción. ","")&IF(E18="BAJO SS (XLIB CUBRE)","Disponible bajo el SS; depende de liberar "&TEXT(J18,"#,##0")&" kg"&IF(ISNUMBER(K18)," el "&TEXT(K18,"dd-mm"),"")&". ","")&IF(W18="SÍ","Stock parece sano pero "&TEXT(L18,"#,##0")&" kg no pasan filtro "&Stock_Seguridad!O18&": sin ellos queda bajo el SS para esa cadena. ","")&IF(E18="SOBRE MAX VENDIBLE","Sobrestock vs vida útil: frenar producción/activar venta. ","")&IF(N(N18)>=Parametros!$B$17,TEXT(N18,"#,##0")&" kg ya no los acepta ninguna cadena: venta intermedia/liquidación. ","")&IF(N(M18)>=Parametros!$B$17,TEXT(M18,"#,##0")&" kg a punto de salir del filtro: despachar primero (FEFO). ","")&IF(Y18="SÍ","Pedidos "&IF(N(U18)>0,"sobre","bajo")&" FCST "&TEXT(ABS(N(U18)),"0%")&": revisar forecast con KAM.","") -> 3,672 kg a punto de salir del filtro: despachar primero (FEFO).
A19: =Stock_Seguridad!A19 -> 30000305 | B19: =Stock_Seguridad!B19 -> YOGU YOGU FRUTILLA 30X200GR | C19: =Stock_Seguridad!C19 -> LECHES LIQUIDAS | D19: =Stock_Seguridad!F19 -> AX | E19: =Stock_Seguridad!X19 -> OK | F19: =Stock_Seguridad!W19 -> 3.8535218 | G19: =Stock_Seguridad!T19 -> 96918 | H19: =Stock_Seguridad!R19 -> 6844.4321 | I19: =Stock_Seguridad!S19 -> 31994.932 | J19: =Stock_Seguridad!U19 -> 0 | L19: 960 | M19: 41184 | N19: 0 | O19: 0.13009032 | P19: =IF(ISNUMBER(Stock_Seguridad!N19),Stock_Seguridad!N19,"") -> 0.22040816 | Q19: =IF(AND(ISNUMBER(O19),ISNUMBER(P19)),P19-O19,"") -> 0.090317843 | R19: =MAX(0,G19-N(L19)) -> 95958 | S19: =SUMIFS(Cadenas_vs_FCST!$D$17:$D$652,Cadenas_vs_FCST!$A$17:$A$652,A19) -> 83280 | T19: =SUMIFS(Cadenas_vs_FCST!$E$17:$E$652,Cadenas_vs_FCST!$A$17:$A$652,A19) -> 85037.805 | U19: =IF(T19>0,S19/T19-1,"") -> -0.020670867 | V19: =IF(OR(E19="BAJO SS",E19="BAJO SS (XLIB CUBRE)"),"SÍ","") | W19: =IF(AND(V19="",N(L19)>=Parametros!$B$17,G19>=H19,R19<H19),"SÍ","") | X19: =IF(OR(E19="SOBRE MAX VENDIBLE",N(N19)>=Parametros!$B$17,N(M19)>=Parametros!$B$17),"SÍ","") -> SÍ | Y19: =IF(AND(ISNUMBER(U19),MAX(S19,T19)>=Parametros!$B$15,ABS(N(U19))>Parametros!$B$14),"SÍ","") | Z19: =COUNTIF(V19:Y19,"SÍ") -> 1 | AA19: =(3*(V19="SÍ")+2*(W19="SÍ")+2*(X19="SÍ")+(Y19="SÍ"))*IF(LEFT(D19,1)="A",3,IF(OR(LEFT(D19,1)="B",D19="SIN HIST"),2,1)) -> 6 | AB19: =IF(AA19>=9,"1-ALTA",IF(AA19>=4,"2-MEDIA",IF(AA19>0,"3-BAJA",""))) -> 2-MEDIA | AC19: =IF(E19="BAJO SS","Stock + XLIB bajo el SS: riesgo real de quiebre, adelantar producción. ","")&IF(E19="BAJO SS (XLIB CUBRE)","Disponible bajo el SS; depende de liberar "&TEXT(J19,"#,##0")&" kg"&IF(ISNUMBER(K19)," el "&TEXT(K19,"dd-mm"),"")&". ","")&IF(W19="SÍ","Stock parece sano pero "&TEXT(L19,"#,##0")&" kg no pasan filtro "&Stock_Seguridad!O19&": sin ellos queda bajo el SS para esa cadena. ","")&IF(E19="SOBRE MAX VENDIBLE","Sobrestock vs vida útil: frenar producción/activar venta. ","")&IF(N(N19)>=Parametros!$B$17,TEXT(N19,"#,##0")&" kg ya no los acepta ninguna cadena: venta intermedia/liquidación. ","")&IF(N(M19)>=Parametros!$B$17,TEXT(M19,"#,##0")&" kg a punto de salir del filtro: despachar primero (FEFO). ","")&IF(Y19="SÍ","Pedidos "&IF(N(U19)>0,"sobre","bajo")&" FCST "&TEXT(ABS(N(U19)),"0%")&": revisar forecast con KAM.","") -> 41,184 kg a punto de salir del filtro: despachar primero (FEFO).
A20: =Stock_Seguridad!A20 -> 30002329 | B20: =Stock_Seguridad!B20 -> LECHE LONCO PROTEIN CAPPUCCINO 30X200ML | C20: =Stock_Seguridad!C20 -> LECHES LIQUIDAS | D20: =Stock_Seguridad!F20 -> AX | E20: =Stock_Seguridad!X20 -> OK | F20: =Stock_Seguridad!W20 -> 3.6094252 | G20: =Stock_Seguridad!T20 -> 86946 | H20: =Stock_Seguridad!R20 -> 11825.155 | I20: =Stock_Seguridad!S20 -> 35913.755 | J20: =Stock_Seguridad!U20 -> 0 | L20: 0 | M20: 0 | N20: 0 | O20: 0.10672072 | P20: =IF(ISNUMBER(Stock_Seguridad!N20),Stock_Seguridad!N20,"") | Q20: =IF(AND(ISNUMBER(O20),ISNUMBER(P20)),P20-O20,"") | R20: =MAX(0,G20-N(L20)) -> 86946 | S20: =SUMIFS(Cadenas_vs_FCST!$D$17:$D$652,Cadenas_vs_FCST!$A$17:$A$652,A20) -> 83460 | T20: =SUMIFS(Cadenas_vs_FCST!$E$17:$E$652,Cadenas_vs_FCST!$A$17:$A$652,A20) -> 81679.087 | U20: =IF(T20>0,S20/T20-1,"") -> 0.021803783 | V20: =IF(OR(E20="BAJO SS",E20="BAJO SS (XLIB CUBRE)"),"SÍ","") | W20: =IF(AND(V20="",N(L20)>=Parametros!$B$17,G20>=H20,R20<H20),"SÍ","") | X20: =IF(OR(E20="SOBRE MAX VENDIBLE",N(N20)>=Parametros!$B$17,N(M20)>=Parametros!$B$17),"SÍ","") | Y20: =IF(AND(ISNUMBER(U20),MAX(S20,T20)>=Parametros!$B$15,ABS(N(U20))>Parametros!$B$14),"SÍ","") | Z20: =COUNTIF(V20:Y20,"SÍ") -> 0 | AA20: =(3*(V20="SÍ")+2*(W20="SÍ")+2*(X20="SÍ")+(Y20="SÍ"))*IF(LEFT(D20,1)="A",3,IF(OR(LEFT(D20,1)="B",D20="SIN HIST"),2,1)) -> 0 | AB20: =IF(AA20>=9,"1-ALTA",IF(AA20>=4,"2-MEDIA",IF(AA20>0,"3-BAJA",""))) | AC20: =IF(E20="BAJO SS","Stock + XLIB bajo el SS: riesgo real de quiebre, adelantar producción. ","")&IF(E20="BAJO SS (XLIB CUBRE)","Disponible bajo el SS; depende de liberar "&TEXT(J20,"#,##0")&" kg"&IF(ISNUMBER(K20)," el "&TEXT(K20,"dd-mm"),"")&". ","")&IF(W20="SÍ","Stock parece sano pero "&TEXT(L20,"#,##0")&" kg no pasan filtro "&Stock_Seguridad!O20&": sin ellos queda bajo el SS para esa cadena. ","")&IF(E20="SOBRE MAX VENDIBLE","Sobrestock vs vida útil: frenar producción/activar venta. ","")&IF(N(N20)>=Parametros!$B$17,TEXT(N20,"#,##0")&" kg ya no los acepta ninguna cadena: venta intermedia/liquidación. ","")&IF(N(M20)>=Parametros!$B$17,TEXT(M20,"#,##0")&" kg a punto de salir del filtro: despachar primero (FEFO). ","")&IF(Y20="SÍ","Pedidos "&IF(N(U20)>0,"sobre","bajo")&" FCST "&TEXT(ABS(N(U20)),"0%")&": revisar forecast con KAM.","")
A21: =Stock_Seguridad!A21 -> 30000384 | B21: =Stock_Seguridad!B21 -> CREMA S/LAC LONCO 30X200ML | C21: =Stock_Seguridad!C21 -> CREMA | D21: =Stock_Seguridad!F21 -> AX | E21: =Stock_Seguridad!X21 -> OK | F21: =Stock_Seguridad!W21 -> 2.382303 | G21: =Stock_Seguridad!T21 -> 56862 | H21: =Stock_Seguridad!R21 -> 15904.195 | I21: =Stock_Seguridad!S21 -> 39772.695 | J21: =Stock_Seguridad!U21 -> 0 | L21: 48 | M21: 168 | N21: 0 | O21: 0.10590895 | P21: =IF(ISNUMBER(Stock_Seguridad!N21),Stock_Seguridad!N21,"") -> 0.25925926 | Q21: =IF(AND(ISNUMBER(O21),ISNUMBER(P21)),P21-O21,"") -> 0.15335031 | R21: =MAX(0,G21-N(L21)) -> 56814 | S21: =SUMIFS(Cadenas_vs_FCST!$D$17:$D$652,Cadenas_vs_FCST!$A$17:$A$652,A21) -> 80772 | T21: =SUMIFS(Cadenas_vs_FCST!$E$17:$E$652,Cadenas_vs_FCST!$A$17:$A$652,A21) -> 72959.844 | U21: =IF(T21>0,S21/T21-1,"") -> 0.10707473 | V21: =IF(OR(E21="BAJO SS",E21="BAJO SS (XLIB CUBRE)"),"SÍ","") | W21: =IF(AND(V21="",N(L21)>=Parametros!$B$17,G21>=H21,R21<H21),"SÍ","") | X21: =IF(OR(E21="SOBRE MAX VENDIBLE",N(N21)>=Parametros!$B$17,N(M21)>=Parametros!$B$17),"SÍ","") | Y21: =IF(AND(ISNUMBER(U21),MAX(S21,T21)>=Parametros!$B$15,ABS(N(U21))>Parametros!$B$14),"SÍ","") | Z21: =COUNTIF(V21:Y21,"SÍ") -> 0 | AA21: =(3*(V21="SÍ")+2*(W21="SÍ")+2*(X21="SÍ")+(Y21="SÍ"))*IF(LEFT(D21,1)="A",3,IF(OR(LEFT(D21,1)="B",D21="SIN HIST"),2,1)) -> 0 | AB21: =IF(AA21>=9,"1-ALTA",IF(AA21>=4,"2-MEDIA",IF(AA21>0,"3-BAJA",""))) | AC21: =IF(E21="BAJO SS","Stock + XLIB bajo el SS: riesgo real de quiebre, adelantar producción. ","")&IF(E21="BAJO SS (XLIB CUBRE)","Disponible bajo el SS; depende de liberar "&TEXT(J21,"#,##0")&" kg"&IF(ISNUMBER(K21)," el "&TEXT(K21,"dd-mm"),"")&". ","")&IF(W21="SÍ","Stock parece sano pero "&TEXT(L21,"#,##0")&" kg no pasan filtro "&Stock_Seguridad!O21&": sin ellos queda bajo el SS para esa cadena. ","")&IF(E21="SOBRE MAX VENDIBLE","Sobrestock vs vida útil: frenar producción/activar venta. ","")&IF(N(N21)>=Parametros!$B$17,TEXT(N21,"#,##0")&" kg ya no los acepta ninguna cadena: venta intermedia/liquidación. ","")&IF(N(M21)>=Parametros!$B$17,TEXT(M21,"#,##0")&" kg a punto de salir del filtro: despachar primero (FEFO). ","")&IF(Y21="SÍ","Pedidos "&IF(N(U21)>0,"sobre","bajo")&" FCST "&TEXT(ABS(N(U21)),"0%")&": revisar forecast con KAM.","")
A22: =Stock_Seguridad!A22 -> 30002099 | B22: =Stock_Seguridad!B22 -> NECTAR WATTS TUTTIFLLA SIXPACK 30X200ML | C22: =Stock_Seguridad!C22 -> JUGOS Y NECTARES | D22: =Stock_Seguridad!F22 -> AY | E22: =Stock_Seguridad!X22 -> OK | F22: =Stock_Seguridad!W22 -> 6.8047919 | G22: =Stock_Seguridad!T22 -> 146766 | H22: =Stock_Seguridad!R22 -> 52827.681 | I22: =Stock_Seguridad!S22 -> 74397.481 | J22: =Stock_Seguridad!U22 -> 12 | K22: 46317 | L22: 198 | M22: 0 | N22: 0 | O22: 0.047139353 | P22: =IF(ISNUMBER(Stock_Seguridad!N22),Stock_Seguridad!N22,"") -> 0.19444444 | Q22: =IF(AND(ISNUMBER(O22),ISNUMBER(P22)),P22-O22,"") -> 0.14730509 | R22: =MAX(0,G22-N(L22)) -> 146568 | S22: =SUMIFS(Cadenas_vs_FCST!$D$17:$D$652,Cadenas_vs_FCST!$A$17:$A$652,A22) -> 119580 | T22: =SUMIFS(Cadenas_vs_FCST!$E$17:$E$652,Cadenas_vs_FCST!$A$17:$A$652,A22) -> 127888.8 | U22: =IF(T22>0,S22/T22-1,"") -> -0.064968964 | V22: =IF(OR(E22="BAJO SS",E22="BAJO SS (XLIB CUBRE)"),"SÍ","") | W22: =IF(AND(V22="",N(L22)>=Parametros!$B$17,G22>=H22,R22<H22),"SÍ","") | X22: =IF(OR(E22="SOBRE MAX VENDIBLE",N(N22)>=Parametros!$B$17,N(M22)>=Parametros!$B$17),"SÍ","") | Y22: =IF(AND(ISNUMBER(U22),MAX(S22,T22)>=Parametros!$B$15,ABS(N(U22))>Parametros!$B$14),"SÍ","") | Z22: =COUNTIF(V22:Y22,"SÍ") -> 0 | AA22: =(3*(V22="SÍ")+2*(W22="SÍ")+2*(X22="SÍ")+(Y22="SÍ"))*IF(LEFT(D22,1)="A",3,IF(OR(LEFT(D22,1)="B",D22="SIN HIST"),2,1)) -> 0 | AB22: =IF(AA22>=9,"1-ALTA",IF(AA22>=4,"2-MEDIA",IF(AA22>0,"3-BAJA",""))) | AC22: =IF(E22="BAJO SS","Stock + XLIB bajo el SS: riesgo real de quiebre, adelantar producción. ","")&IF(E22="BAJO SS (XLIB CUBRE)","Disponible bajo el SS; depende de liberar "&TEXT(J22,"#,##0")&" kg"&IF(ISNUMBER(K22)," el "&TEXT(K22,"dd-mm"),"")&". ","")&IF(W22="SÍ","Stock parece sano pero "&TEXT(L22,"#,##0")&" kg no pasan filtro "&Stock_Seguridad!O22&": sin ellos queda bajo el SS para esa cadena. ","")&IF(E22="SOBRE MAX VENDIBLE","Sobrestock vs vida útil: frenar producción/activar venta. ","")&IF(N(N22)>=Parametros!$B$17,TEXT(N22,"#,##0")&" kg ya no los acepta ninguna cadena: venta intermedia/liquidación. ","")&IF(N(M22)>=Parametros!$B$17,TEXT(M22,"#,##0")&" kg a punto de salir del filtro: despachar primero (FEFO). ","")&IF(Y22="SÍ","Pedidos "&IF(N(U22)>0,"sobre","bajo")&" FCST "&TEXT(ABS(N(U22)),"0%")&": revisar forecast con KAM.","")
A23: =Stock_Seguridad!A23 -> 30002066 | B23: =Stock_Seguridad!B23 -> LECHE FRUTILLA LONCOLECHE 12X1LT | C23: =Stock_Seguridad!C23 -> LECHES LIQUIDAS | D23: =Stock_Seguridad!F23 -> AX | E23: =Stock_Seguridad!X23 -> BAJO SS | F23: =Stock_Seguridad!W23 -> 1.8335788 | G23: =Stock_Seguridad!T23 -> 34860 | H23: =Stock_Seguridad!R23 -> 41008.139 | I23: =Stock_Seguridad!S23 -> 60020.139 | J23: =Stock_Seguridad!U23 -> 0 | L23: 492 | M23: 0 | N23: 36 | O23: 0.037311532 | P23: =IF(ISNUMBER(Stock_Seguridad!N23),Stock_Seguridad!N23,"") -> 0.23831776 | Q23: =IF(AND(ISNUMBER(O23),ISNUMBER(P23)),P23-O23,"") -> 0.20100623 | R23: =MAX(0,G23-N(L23)) -> 34368 | S23: =SUMIFS(Cadenas_vs_FCST!$D$17:$D$652,Cadenas_vs_FCST!$A$17:$A$652,A23) -> 108816 | T23: =SUMIFS(Cadenas_vs_FCST!$E$17:$E$652,Cadenas_vs_FCST!$A$17:$A$652,A23) -> 38172.57 | U23: =IF(T23>0,S23/T23-1,"") -> 1.8506334 | V23: =IF(OR(E23="BAJO SS",E23="BAJO SS (XLIB CUBRE)"),"SÍ","") -> SÍ | W23: =IF(AND(V23="",N(L23)>=Parametros!$B$17,G23>=H23,R23<H23),"SÍ","") | X23: =IF(OR(E23="SOBRE MAX VENDIBLE",N(N23)>=Parametros!$B$17,N(M23)>=Parametros!$B$17),"SÍ","") | Y23: =IF(AND(ISNUMBER(U23),MAX(S23,T23)>=Parametros!$B$15,ABS(N(U23))>Parametros!$B$14),"SÍ","") -> SÍ | Z23: =COUNTIF(V23:Y23,"SÍ") -> 2 | AA23: =(3*(V23="SÍ")+2*(W23="SÍ")+2*(X23="SÍ")+(Y23="SÍ"))*IF(LEFT(D23,1)="A",3,IF(OR(LEFT(D23,1)="B",D23="SIN HIST"),2,1)) -> 12 | AB23: =IF(AA23>=9,"1-ALTA",IF(AA23>=4,"2-MEDIA",IF(AA23>0,"3-BAJA",""))) -> 1-ALTA | AC23: =IF(E23="BAJO SS","Stock + XLIB bajo el SS: riesgo real de quiebre, adelantar producción. ","")&IF(E23="BAJO SS (XLIB CUBRE)","Disponible bajo el SS; depende de liberar "&TEXT(J23,"#,##0")&" kg"&IF(ISNUMBER(K23)," el "&TEXT(K23,"dd-mm"),"")&". ","")&IF(W23="SÍ","Stock parece sano pero "&TEXT(L23,"#,##0")&" kg no pasan filtro "&Stock_Seguridad!O23&": sin ellos queda bajo el SS para esa cadena. ","")&IF(E23="SOBRE MAX VENDIBLE","Sobrestock vs vida útil: frenar producción/activar venta. ","")&IF(N(N23)>=Parametros!$B$17,TEXT(N23,"#,##0")&" kg ya no los acepta ninguna cadena: venta intermedia/liquidación. ","")&IF(N(M23)>=Parametros!$B$17,TEXT(M23,"#,##0")&" kg a punto de salir del filtro: despachar primero (FEFO). ","")&IF(Y23="SÍ","Pedidos "&IF(N(U23)>0,"sobre","bajo")&" FCST "&TEXT(ABS(N(U23)),"0%")&": revisar forecast con KAM.","") -> Stock + XLIB bajo el SS: riesgo real de quiebre, adelantar producción. Pedidos sobre FCST 185%: revisar forecast con KAM.
A24: =Stock_Seguridad!A24 -> 30002065 | B24: =Stock_Seguridad!B24 -> LECHE CHOCOLATE LONCOLECHE 12X1LT | C24: =Stock_Seguridad!C24 -> LECHES LIQUIDAS | D24: =Stock_Seguridad!F24 -> BY | E24: =Stock_Seguridad!X24 -> BAJO P.REORDEN | F24: =Stock_Seguridad!W24 -> 0.67784505 | G24: =Stock_Seguridad!T24 -> 11520 | H24: =Stock_Seguridad!R24 -> 8108.6827 | I24: =Stock_Seguridad!S24 -> 26590.783 | J24: =Stock_Seguridad!U24 -> 1008 | K24: 46320 | L24: 0 | M24: 96 | N24: 0 | O24: 0.071082375 | P24: =IF(ISNUMBER(Stock_Seguridad!N24),Stock_Seguridad!N24,"") -> 0.23831776 | Q24: =IF(AND(ISNUMBER(O24),ISNUMBER(P24)),P24-O24,"") -> 0.16723538 | R24: =MAX(0,G24-N(L24)) -> 11520 | S24: =SUMIFS(Cadenas_vs_FCST!$D$17:$D$652,Cadenas_vs_FCST!$A$17:$A$652,A24) -> 28884 | T24: =SUMIFS(Cadenas_vs_FCST!$E$17:$E$652,Cadenas_vs_FCST!$A$17:$A$652,A24) -> 31045.235 | U24: =IF(T24>0,S24/T24-1,"") -> -0.069615674 | V24: =IF(OR(E24="BAJO SS",E24="BAJO SS (XLIB CUBRE)"),"SÍ","") | W24: =IF(AND(V24="",N(L24)>=Parametros!$B$17,G24>=H24,R24<H24),"SÍ","") | X24: =IF(OR(E24="SOBRE MAX VENDIBLE",N(N24)>=Parametros!$B$17,N(M24)>=Parametros!$B$17),"SÍ","") | Y24: =IF(AND(ISNUMBER(U24),MAX(S24,T24)>=Parametros!$B$15,ABS(N(U24))>Parametros!$B$14),"SÍ","") | Z24: =COUNTIF(V24:Y24,"SÍ") -> 0 | AA24: =(3*(V24="SÍ")+2*(W24="SÍ")+2*(X24="SÍ")+(Y24="SÍ"))*IF(LEFT(D24,1)="A",3,IF(OR(LEFT(D24,1)="B",D24="SIN HIST"),2,1)) -> 0 | AB24: =IF(AA24>=9,"1-ALTA",IF(AA24>=4,"2-MEDIA",IF(AA24>0,"3-BAJA",""))) | AC24: =IF(E24="BAJO SS","Stock + XLIB bajo el SS: riesgo real de quiebre, adelantar producción. ","")&IF(E24="BAJO SS (XLIB CUBRE)","Disponible bajo el SS; depende de liberar "&TEXT(J24,"#,##0")&" kg"&IF(ISNUMBER(K24)," el "&TEXT(K24,"dd-mm"),"")&". ","")&IF(W24="SÍ","Stock parece sano pero "&TEXT(L24,"#,##0")&" kg no pasan filtro "&Stock_Seguridad!O24&": sin ellos queda bajo el SS para esa cadena. ","")&IF(E24="SOBRE MAX VENDIBLE","Sobrestock vs vida útil: frenar producción/activar venta. ","")&IF(N(N24)>=Parametros!$B$17,TEXT(N24,"#,##0")&" kg ya no los acepta ninguna cadena: venta intermedia/liquidación. ","")&IF(N(M24)>=Parametros!$B$17,TEXT(M24,"#,##0")&" kg a punto de salir del filtro: despachar primero (FEFO). ","")&IF(Y24="SÍ","Pedidos "&IF(N(U24)>0,"sobre","bajo")&" FCST "&TEXT(ABS(N(U24)),"0%")&": revisar forecast con KAM.","")
A25: =Stock_Seguridad!A25 -> 30000401 | B25: =Stock_Seguridad!B25 -> LECHE LONCO FRUTILLA 30X200ML | C25: =Stock_Seguridad!C25 -> LECHES LIQUIDAS | D25: =Stock_Seguridad!F25 -> AY | E25: =Stock_Seguridad!X25 -> OK | F25: =Stock_Seguridad!W25 -> 5.1576248 | G25: =Stock_Seguridad!T25 -> 91698 | H25: =Stock_Seguridad!R25 -> 47041.835 | I25: =Stock_Seguridad!S25 -> 64976.835 | J25: =Stock_Seguridad!U25 -> 804 | K25: 46313 | L25: 5064 | M25: 4008 | N25: 0 | O25: 0.091508271 | P25: =IF(ISNUMBER(Stock_Seguridad!N25),Stock_Seguridad!N25,"") -> 0.23831776 | Q25: =IF(AND(ISNUMBER(O25),ISNUMBER(P25)),P25-O25,"") -> 0.14680949 | R25: =MAX(0,G25-N(L25)) -> 86634 | S25: =SUMIFS(Cadenas_vs_FCST!$D$17:$D$652,Cadenas_vs_FCST!$A$17:$A$652,A25) -> 140712 | T25: =SUMIFS(Cadenas_vs_FCST!$E$17:$E$652,Cadenas_vs_FCST!$A$17:$A$652,A25) -> 122422.75 | U25: =IF(T25>0,S25/T25-1,"") -> 0.14939421 | V25: =IF(OR(E25="BAJO SS",E25="BAJO SS (XLIB CUBRE)"),"SÍ","") | W25: =IF(AND(V25="",N(L25)>=Parametros!$B$17,G25>=H25,R25<H25),"SÍ","") | X25: =IF(OR(E25="SOBRE MAX VENDIBLE",N(N25)>=Parametros!$B$17,N(M25)>=Parametros!$B$17),"SÍ","") -> SÍ | Y25: =IF(AND(ISNUMBER(U25),MAX(S25,T25)>=Parametros!$B$15,ABS(N(U25))>Parametros!$B$14),"SÍ","") | Z25: =COUNTIF(V25:Y25,"SÍ") -> 1 | AA25: =(3*(V25="SÍ")+2*(W25="SÍ")+2*(X25="SÍ")+(Y25="SÍ"))*IF(LEFT(D25,1)="A",3,IF(OR(LEFT(D25,1)="B",D25="SIN HIST"),2,1)) -> 6 | AB25: =IF(AA25>=9,"1-ALTA",IF(AA25>=4,"2-MEDIA",IF(AA25>0,"3-BAJA",""))) -> 2-MEDIA | AC25: =IF(E25="BAJO SS","Stock + XLIB bajo el SS: riesgo real de quiebre, adelantar producción. ","")&IF(E25="BAJO SS (XLIB CUBRE)","Disponible bajo el SS; depende de liberar "&TEXT(J25,"#,##0")&" kg"&IF(ISNUMBER(K25)," el "&TEXT(K25,"dd-mm"),"")&". ","")&IF(W25="SÍ","Stock parece sano pero "&TEXT(L25,"#,##0")&" kg no pasan filtro "&Stock_Seguridad!O25&": sin ellos queda bajo el SS para esa cadena. ","")&IF(E25="SOBRE MAX VENDIBLE","Sobrestock vs vida útil: frenar producción/activar venta. ","")&IF(N(N25)>=Parametros!$B$17,TEXT(N25,"#,##0")&" kg ya no los acepta ninguna cadena: venta intermedia/liquidación. ","")&IF(N(M25)>=Parametros!$B$17,TEXT(M25,"#,##0")&" kg a punto de salir del filtro: despachar primero (FEFO). ","")&IF(Y25="SÍ","Pedidos "&IF(N(U25)>0,"sobre","bajo")&" FCST "&TEXT(ABS(N(U25)),"0%")&": revisar forecast con KAM.","") -> 4,008 kg a punto de salir del filtro: despachar primero (FEFO).
